2016-08-18 11:29:23,096 [Thread-28:18216] [django.request:182] [WARNING]- Not Found: /favicon.ico
2016-08-23 16:44:42,100 [Thread-15:123145312813056] [django.request:182] [WARNING]- Not Found: /favicon.ico
2016-08-23 16:45:28,844 [Thread-21:123145312813056] [django.request:284] [ERROR]- Internal Server Error: /mockPlatform/kernal/saveMockShift
Traceback (most recent call last):
  File "/usr/local/opt/pyenv/versions/3.5.1/lib/python3.5/site-packages/django/db/models/options.py", line 580, in get_field
    return self.fields_map[field_name]
KeyError: 'status'

During handling of the above exception, another exception occurred:

Traceback (most recent call last):
  File "/usr/local/opt/pyenv/versions/3.5.1/lib/python3.5/site-packages/django/core/handlers/base.py", line 149, in get_response
    response = self.process_exception_by_middleware(e, request)
  File "/usr/local/opt/pyenv/versions/3.5.1/lib/python3.5/site-packages/django/core/handlers/base.py", line 147, in get_response
    response = wrapped_callback(request, *callback_args, **callback_kwargs)
  File "/usr/local/opt/pyenv/versions/3.5.1/lib/python3.5/site-packages/django/views/decorators/csrf.py", line 58, in wrapped_view
    return view_func(*args, **kwargs)
  File "/Users/zhangyufeng/Documents/iwater_Documents/QualityAssuranse/iwaterMock/totest/views/mock_shift.py", line 42, in save_mock_shift
    mock_shift.objects.filter(id=1).update(is_open=data_list["isOpen"], status=data_list["status"])
  File "/usr/local/opt/pyenv/versions/3.5.1/lib/python3.5/site-packages/django/db/models/query.py", line 626, in update
    query.add_update_values(kwargs)
  File "/usr/local/opt/pyenv/versions/3.5.1/lib/python3.5/site-packages/django/db/models/sql/subqueries.py", line 126, in add_update_values
    field = self.get_meta().get_field(name)
  File "/usr/local/opt/pyenv/versions/3.5.1/lib/python3.5/site-packages/django/db/models/options.py", line 582, in get_field
    raise FieldDoesNotExist('%s has no field named %r' % (self.object_name, field_name))
django.core.exceptions.FieldDoesNotExist: mock_shift has no field named 'status'
2016-08-23 16:46:36,000 [Thread-26:123145312813056] [django.request:284] [ERROR]- Internal Server Error: /mockPlatform/kernal/saveMockShift
Traceback (most recent call last):
  File "/usr/local/opt/pyenv/versions/3.5.1/lib/python3.5/site-packages/django/db/models/options.py", line 580, in get_field
    return self.fields_map[field_name]
KeyError: 'status'

During handling of the above exception, another exception occurred:

Traceback (most recent call last):
  File "/usr/local/opt/pyenv/versions/3.5.1/lib/python3.5/site-packages/django/core/handlers/base.py", line 149, in get_response
    response = self.process_exception_by_middleware(e, request)
  File "/usr/local/opt/pyenv/versions/3.5.1/lib/python3.5/site-packages/django/core/handlers/base.py", line 147, in get_response
    response = wrapped_callback(request, *callback_args, **callback_kwargs)
  File "/usr/local/opt/pyenv/versions/3.5.1/lib/python3.5/site-packages/django/views/decorators/csrf.py", line 58, in wrapped_view
    return view_func(*args, **kwargs)
  File "/Users/zhangyufeng/Documents/iwater_Documents/QualityAssuranse/iwaterMock/totest/views/mock_shift.py", line 42, in save_mock_shift
    mock_shift.objects.filter(id=1).update(is_open=data_list["isOpen"], status=data_list["status"])
  File "/usr/local/opt/pyenv/versions/3.5.1/lib/python3.5/site-packages/django/db/models/query.py", line 626, in update
    query.add_update_values(kwargs)
  File "/usr/local/opt/pyenv/versions/3.5.1/lib/python3.5/site-packages/django/db/models/sql/subqueries.py", line 126, in add_update_values
    field = self.get_meta().get_field(name)
  File "/usr/local/opt/pyenv/versions/3.5.1/lib/python3.5/site-packages/django/db/models/options.py", line 582, in get_field
    raise FieldDoesNotExist('%s has no field named %r' % (self.object_name, field_name))
django.core.exceptions.FieldDoesNotExist: mock_shift has no field named 'status'
2016-08-23 16:47:59,595 [Thread-57:123145312813056] [django.request:284] [ERROR]- Internal Server Error: /mockPlatform/kernal/saveMockShift
Traceback (most recent call last):
  File "/usr/local/opt/pyenv/versions/3.5.1/lib/python3.5/site-packages/django/db/models/options.py", line 580, in get_field
    return self.fields_map[field_name]
KeyError: 'status'

During handling of the above exception, another exception occurred:

Traceback (most recent call last):
  File "/usr/local/opt/pyenv/versions/3.5.1/lib/python3.5/site-packages/django/core/handlers/base.py", line 149, in get_response
    response = self.process_exception_by_middleware(e, request)
  File "/usr/local/opt/pyenv/versions/3.5.1/lib/python3.5/site-packages/django/core/handlers/base.py", line 147, in get_response
    response = wrapped_callback(request, *callback_args, **callback_kwargs)
  File "/usr/local/opt/pyenv/versions/3.5.1/lib/python3.5/site-packages/django/views/decorators/csrf.py", line 58, in wrapped_view
    return view_func(*args, **kwargs)
  File "/Users/zhangyufeng/Documents/iwater_Documents/QualityAssuranse/iwaterMock/totest/views/mock_shift.py", line 42, in save_mock_shift
    mock_shift.objects.filter(id=1).update(is_open=data_list["isOpen"], status=data_list["status"])
  File "/usr/local/opt/pyenv/versions/3.5.1/lib/python3.5/site-packages/django/db/models/query.py", line 626, in update
    query.add_update_values(kwargs)
  File "/usr/local/opt/pyenv/versions/3.5.1/lib/python3.5/site-packages/django/db/models/sql/subqueries.py", line 126, in add_update_values
    field = self.get_meta().get_field(name)
  File "/usr/local/opt/pyenv/versions/3.5.1/lib/python3.5/site-packages/django/db/models/options.py", line 582, in get_field
    raise FieldDoesNotExist('%s has no field named %r' % (self.object_name, field_name))
django.core.exceptions.FieldDoesNotExist: mock_shift has no field named 'status'
2016-08-23 17:08:35,396 [Thread-2:123145312813056] [django.request:182] [WARNING]- Not Found: /testInstall$
